[2021-03-27 17:11:26,122: CRITICAL/MainProcess] beat raised exception <class 'EOFError'>: EOFError('Ran out of input')
Traceback (most recent call last):
  File "/home/www/env/lib/python3.9/site-packages/kombu/utils/objects.py", line 41, in __get__
    return obj.__dict__[self.__name__]
KeyError: 'scheduler'

During handling of the above exception, another exception occurred:

Traceback (most recent call last):
  File "/home/www/.python/lib/python3.9/shelve.py", line 111, in __getitem__
    value = self.cache[key]
KeyError: 'entries'

During handling of the above exception, another exception occurred:

Traceback (most recent call last):
  File "/home/www/env/lib/python3.9/site-packages/celery/apps/beat.py", line 105, in start_scheduler
    service.start()
  File "/home/www/env/lib/python3.9/site-packages/celery/beat.py", line 618, in start
    humanize_seconds(self.scheduler.max_interval))
  File "/home/www/env/lib/python3.9/site-packages/kombu/utils/objects.py", line 43, in __get__
    value = obj.__dict__[self.__name__] = self.__get(obj)
  File "/home/www/env/lib/python3.9/site-packages/celery/beat.py", line 662, in scheduler
    return self.get_scheduler()
  File "/home/www/env/lib/python3.9/site-packages/celery/beat.py", line 653, in get_scheduler
    return symbol_by_name(self.scheduler_cls, aliases=aliases)(
  File "/home/www/env/lib/python3.9/site-packages/celery/beat.py", line 497, in __init__
    Scheduler.__init__(self, *args, **kwargs)
  File "/home/www/env/lib/python3.9/site-packages/celery/beat.py", line 253, in __init__
    self.setup_schedule()
  File "/home/www/env/lib/python3.9/site-packages/celery/beat.py", line 525, in setup_schedule
    self._create_schedule()
  File "/home/www/env/lib/python3.9/site-packages/celery/beat.py", line 554, in _create_schedule
    self._store['entries']
  File "/home/www/.python/lib/python3.9/shelve.py", line 114, in __getitem__
    value = Unpickler(f).load()
EOFError: Ran out of input
[2021-03-27 17:11:26,125: WARNING/MainProcess] Aborted!
celery beat v5.0.5 (singularity) is starting.
__    -    ... __   -        _
LocalTime -> 2021-03-27 17:11:26
Configuration ->
    . broker -> redis://localhost:6379/0
    . loader -> celery.loaders.app.AppLoader
    . scheduler -> celery.beat.PersistentScheduler
    . db -> celerybeat-schedule
    . logfile -> [stderr]@%WARNING
    . maxinterval -> 5.00 minutes (300s)
[2021-03-27 17:11:28,461: CRITICAL/MainProcess] beat raised exception <class 'EOFError'>: EOFError('Ran out of input')
Traceback (most recent call last):
  File "/home/www/env/lib/python3.9/site-packages/kombu/utils/objects.py", line 41, in __get__
    return obj.__dict__[self.__name__]
KeyError: 'scheduler'

During handling of the above exception, another exception occurred:

Traceback (most recent call last):
  File "/home/www/.python/lib/python3.9/shelve.py", line 111, in __getitem__
    value = self.cache[key]
KeyError: 'entries'

During handling of the above exception, another exception occurred:

Traceback (most recent call last):
  File "/home/www/env/lib/python3.9/site-packages/celery/apps/beat.py", line 105, in start_scheduler
    service.start()
  File "/home/www/env/lib/python3.9/site-packages/celery/beat.py", line 618, in start
    humanize_seconds(self.scheduler.max_interval))
  File "/home/www/env/lib/python3.9/site-packages/kombu/utils/objects.py", line 43, in __get__
    value = obj.__dict__[self.__name__] = self.__get(obj)
  File "/home/www/env/lib/python3.9/site-packages/celery/beat.py", line 662, in scheduler
    return self.get_scheduler()
  File "/home/www/env/lib/python3.9/site-packages/celery/beat.py", line 653, in get_scheduler
    return symbol_by_name(self.scheduler_cls, aliases=aliases)(
  File "/home/www/env/lib/python3.9/site-packages/celery/beat.py", line 497, in __init__
    Scheduler.__init__(self, *args, **kwargs)
  File "/home/www/env/lib/python3.9/site-packages/celery/beat.py", line 253, in __init__
    self.setup_schedule()
  File "/home/www/env/lib/python3.9/site-packages/celery/beat.py", line 525, in setup_schedule
    self._create_schedule()
  File "/home/www/env/lib/python3.9/site-packages/celery/beat.py", line 554, in _create_schedule
    self._store['entries']
  File "/home/www/.python/lib/python3.9/shelve.py", line 114, in __getitem__
    value = Unpickler(f).load()
EOFError: Ran out of input
[2021-03-27 17:11:28,462: WARNING/MainProcess] Aborted!
celery beat v5.0.5 (singularity) is starting.
__    -    ... __   -        _
LocalTime -> 2021-03-27 17:11:28
Configuration ->
    . broker -> redis://localhost:6379/0
    . loader -> celery.loaders.app.AppLoader
    . scheduler -> celery.beat.PersistentScheduler
    . db -> celerybeat-schedule
    . logfile -> [stderr]@%WARNING
    . maxinterval -> 5.00 minutes (300s)
[2021-03-27 17:11:32,879: CRITICAL/MainProcess] beat raised exception <class 'EOFError'>: EOFError('Ran out of input')
Traceback (most recent call last):
  File "/home/www/env/lib/python3.9/site-packages/kombu/utils/objects.py", line 41, in __get__
    return obj.__dict__[self.__name__]
KeyError: 'scheduler'

During handling of the above exception, another exception occurred:

Traceback (most recent call last):
  File "/home/www/.python/lib/python3.9/shelve.py", line 111, in __getitem__
    value = self.cache[key]
KeyError: 'entries'

During handling of the above exception, another exception occurred:

Traceback (most recent call last):
  File "/home/www/env/lib/python3.9/site-packages/celery/apps/beat.py", line 105, in start_scheduler
    service.start()
  File "/home/www/env/lib/python3.9/site-packages/celery/beat.py", line 618, in start
    humanize_seconds(self.scheduler.max_interval))
  File "/home/www/env/lib/python3.9/site-packages/kombu/utils/objects.py", line 43, in __get__
    value = obj.__dict__[self.__name__] = self.__get(obj)
  File "/home/www/env/lib/python3.9/site-packages/celery/beat.py", line 662, in scheduler
    return self.get_scheduler()
  File "/home/www/env/lib/python3.9/site-packages/celery/beat.py", line 653, in get_scheduler
    return symbol_by_name(self.scheduler_cls, aliases=aliases)(
  File "/home/www/env/lib/python3.9/site-packages/celery/beat.py", line 497, in __init__
    Scheduler.__init__(self, *args, **kwargs)
  File "/home/www/env/lib/python3.9/site-packages/celery/beat.py", line 253, in __init__
    self.setup_schedule()
  File "/home/www/env/lib/python3.9/site-packages/celery/beat.py", line 525, in setup_schedule
    self._create_schedule()
  File "/home/www/env/lib/python3.9/site-packages/celery/beat.py", line 554, in _create_schedule
    self._store['entries']
  File "/home/www/.python/lib/python3.9/shelve.py", line 114, in __getitem__
    value = Unpickler(f).load()
EOFError: Ran out of input
[2021-03-27 17:11:32,880: WARNING/MainProcess] Aborted!
celery beat v5.0.5 (singularity) is starting.
__    -    ... __   -        _
LocalTime -> 2021-03-27 17:11:32
Configuration ->
    . broker -> redis://localhost:6379/0
    . loader -> celery.loaders.app.AppLoader
    . scheduler -> celery.beat.PersistentScheduler
    . db -> celerybeat-schedule
    . logfile -> [stderr]@%WARNING
    . maxinterval -> 5.00 minutes (300s)
[2021-03-27 17:11:38,342: CRITICAL/MainProcess] beat raised exception <class 'EOFError'>: EOFError('Ran out of input')
Traceback (most recent call last):
  File "/home/www/env/lib/python3.9/site-packages/kombu/utils/objects.py", line 41, in __get__
    return obj.__dict__[self.__name__]
KeyError: 'scheduler'

During handling of the above exception, another exception occurred:

Traceback (most recent call last):
  File "/home/www/.python/lib/python3.9/shelve.py", line 111, in __getitem__
    value = self.cache[key]
KeyError: 'entries'

During handling of the above exception, another exception occurred:

Traceback (most recent call last):
  File "/home/www/env/lib/python3.9/site-packages/celery/apps/beat.py", line 105, in start_scheduler
    service.start()
  File "/home/www/env/lib/python3.9/site-packages/celery/beat.py", line 618, in start
    humanize_seconds(self.scheduler.max_interval))
  File "/home/www/env/lib/python3.9/site-packages/kombu/utils/objects.py", line 43, in __get__
    value = obj.__dict__[self.__name__] = self.__get(obj)
  File "/home/www/env/lib/python3.9/site-packages/celery/beat.py", line 662, in scheduler
    return self.get_scheduler()
  File "/home/www/env/lib/python3.9/site-packages/celery/beat.py", line 653, in get_scheduler
    return symbol_by_name(self.scheduler_cls, aliases=aliases)(
  File "/home/www/env/lib/python3.9/site-packages/celery/beat.py", line 497, in __init__
    Scheduler.__init__(self, *args, **kwargs)
  File "/home/www/env/lib/python3.9/site-packages/celery/beat.py", line 253, in __init__
    self.setup_schedule()
  File "/home/www/env/lib/python3.9/site-packages/celery/beat.py", line 525, in setup_schedule
    self._create_schedule()
  File "/home/www/env/lib/python3.9/site-packages/celery/beat.py", line 554, in _create_schedule
    self._store['entries']
  File "/home/www/.python/lib/python3.9/shelve.py", line 114, in __getitem__
    value = Unpickler(f).load()
EOFError: Ran out of input
[2021-03-27 17:11:38,343: WARNING/MainProcess] Aborted!
celery beat v5.0.5 (singularity) is starting.
__    -    ... __   -        _
LocalTime -> 2021-03-27 17:11:38
Configuration ->
    . broker -> redis://localhost:6379/0
    . loader -> celery.loaders.app.AppLoader
    . scheduler -> celery.beat.PersistentScheduler
    . db -> celerybeat-schedule
    . logfile -> [stderr]@%WARNING
    . maxinterval -> 5.00 minutes (300s)
[2021-03-27 17:16:46,273: CRITICAL/MainProcess] beat raised exception <class 'EOFError'>: EOFError('Ran out of input')
Traceback (most recent call last):
  File "/home/www/env/lib/python3.9/site-packages/kombu/utils/objects.py", line 41, in __get__
    return obj.__dict__[self.__name__]
KeyError: 'scheduler'

During handling of the above exception, another exception occurred:

Traceback (most recent call last):
  File "/home/www/.python/lib/python3.9/shelve.py", line 111, in __getitem__
    value = self.cache[key]
KeyError: 'entries'

During handling of the above exception, another exception occurred:

Traceback (most recent call last):
  File "/home/www/env/lib/python3.9/site-packages/celery/apps/beat.py", line 105, in start_scheduler
    service.start()
  File "/home/www/env/lib/python3.9/site-packages/celery/beat.py", line 618, in start
    humanize_seconds(self.scheduler.max_interval))
  File "/home/www/env/lib/python3.9/site-packages/kombu/utils/objects.py", line 43, in __get__
    value = obj.__dict__[self.__name__] = self.__get(obj)
  File "/home/www/env/lib/python3.9/site-packages/celery/beat.py", line 662, in scheduler
    return self.get_scheduler()
  File "/home/www/env/lib/python3.9/site-packages/celery/beat.py", line 653, in get_scheduler
    return symbol_by_name(self.scheduler_cls, aliases=aliases)(
  File "/home/www/env/lib/python3.9/site-packages/celery/beat.py", line 497, in __init__
    Scheduler.__init__(self, *args, **kwargs)
  File "/home/www/env/lib/python3.9/site-packages/celery/beat.py", line 253, in __init__
    self.setup_schedule()
  File "/home/www/env/lib/python3.9/site-packages/celery/beat.py", line 525, in setup_schedule
    self._create_schedule()
  File "/home/www/env/lib/python3.9/site-packages/celery/beat.py", line 554, in _create_schedule
    self._store['entries']
  File "/home/www/.python/lib/python3.9/shelve.py", line 114, in __getitem__
    value = Unpickler(f).load()
EOFError: Ran out of input
[2021-03-27 17:16:46,275: WARNING/MainProcess] Aborted!
celery beat v5.0.5 (singularity) is starting.
__    -    ... __   -        _
LocalTime -> 2021-03-27 17:16:46
Configuration ->
    . broker -> redis://localhost:6379/0
    . loader -> celery.loaders.app.AppLoader
    . scheduler -> celery.beat.PersistentScheduler
    . db -> celerybeat-schedule
    . logfile -> [stderr]@%WARNING
    . maxinterval -> 5.00 minutes (300s)
[2021-03-27 17:16:49,715: CRITICAL/MainProcess] beat raised exception <class 'EOFError'>: EOFError('Ran out of input')
Traceback (most recent call last):
  File "/home/www/env/lib/python3.9/site-packages/kombu/utils/objects.py", line 41, in __get__
    return obj.__dict__[self.__name__]
KeyError: 'scheduler'

During handling of the above exception, another exception occurred:

Traceback (most recent call last):
  File "/home/www/.python/lib/python3.9/shelve.py", line 111, in __getitem__
    value = self.cache[key]
KeyError: 'entries'

During handling of the above exception, another exception occurred:

Traceback (most recent call last):
  File "/home/www/env/lib/python3.9/site-packages/celery/apps/beat.py", line 105, in start_scheduler
    service.start()
  File "/home/www/env/lib/python3.9/site-packages/celery/beat.py", line 618, in start
    humanize_seconds(self.scheduler.max_interval))
  File "/home/www/env/lib/python3.9/site-packages/kombu/utils/objects.py", line 43, in __get__
    value = obj.__dict__[self.__name__] = self.__get(obj)
  File "/home/www/env/lib/python3.9/site-packages/celery/beat.py", line 662, in scheduler
    return self.get_scheduler()
  File "/home/www/env/lib/python3.9/site-packages/celery/beat.py", line 653, in get_scheduler
    return symbol_by_name(self.scheduler_cls, aliases=aliases)(
  File "/home/www/env/lib/python3.9/site-packages/celery/beat.py", line 497, in __init__
    Scheduler.__init__(self, *args, **kwargs)
  File "/home/www/env/lib/python3.9/site-packages/celery/beat.py", line 253, in __init__
    self.setup_schedule()
  File "/home/www/env/lib/python3.9/site-packages/celery/beat.py", line 525, in setup_schedule
    self._create_schedule()
  File "/home/www/env/lib/python3.9/site-packages/celery/beat.py", line 554, in _create_schedule
    self._store['entries']
  File "/home/www/.python/lib/python3.9/shelve.py", line 114, in __getitem__
    value = Unpickler(f).load()
EOFError: Ran out of input
[2021-03-27 17:16:49,716: WARNING/MainProcess] Aborted!
celery beat v5.0.5 (singularity) is starting.
__    -    ... __   -        _
LocalTime -> 2021-03-27 17:16:49
Configuration ->
    . broker -> redis://localhost:6379/0
    . loader -> celery.loaders.app.AppLoader
    . scheduler -> celery.beat.PersistentScheduler
    . db -> celerybeat-schedule
    . logfile -> [stderr]@%WARNING
    . maxinterval -> 5.00 minutes (300s)
[2021-03-27 17:16:53,268: CRITICAL/MainProcess] beat raised exception <class 'EOFError'>: EOFError('Ran out of input')
Traceback (most recent call last):
  File "/home/www/env/lib/python3.9/site-packages/kombu/utils/objects.py", line 41, in __get__
    return obj.__dict__[self.__name__]
KeyError: 'scheduler'

During handling of the above exception, another exception occurred:

Traceback (most recent call last):
  File "/home/www/.python/lib/python3.9/shelve.py", line 111, in __getitem__
    value = self.cache[key]
KeyError: 'entries'

During handling of the above exception, another exception occurred:

Traceback (most recent call last):
  File "/home/www/env/lib/python3.9/site-packages/celery/apps/beat.py", line 105, in start_scheduler
    service.start()
  File "/home/www/env/lib/python3.9/site-packages/celery/beat.py", line 618, in start
    humanize_seconds(self.scheduler.max_interval))
  File "/home/www/env/lib/python3.9/site-packages/kombu/utils/objects.py", line 43, in __get__
    value = obj.__dict__[self.__name__] = self.__get(obj)
  File "/home/www/env/lib/python3.9/site-packages/celery/beat.py", line 662, in scheduler
    return self.get_scheduler()
  File "/home/www/env/lib/python3.9/site-packages/celery/beat.py", line 653, in get_scheduler
    return symbol_by_name(self.scheduler_cls, aliases=aliases)(
  File "/home/www/env/lib/python3.9/site-packages/celery/beat.py", line 497, in __init__
    Scheduler.__init__(self, *args, **kwargs)
  File "/home/www/env/lib/python3.9/site-packages/celery/beat.py", line 253, in __init__
    self.setup_schedule()
  File "/home/www/env/lib/python3.9/site-packages/celery/beat.py", line 525, in setup_schedule
    self._create_schedule()
  File "/home/www/env/lib/python3.9/site-packages/celery/beat.py", line 554, in _create_schedule
    self._store['entries']
  File "/home/www/.python/lib/python3.9/shelve.py", line 114, in __getitem__
    value = Unpickler(f).load()
EOFError: Ran out of input
[2021-03-27 17:16:53,269: WARNING/MainProcess] Aborted!
celery beat v5.0.5 (singularity) is starting.
__    -    ... __   -        _
LocalTime -> 2021-03-27 17:16:53
Configuration ->
    . broker -> redis://localhost:6379/0
    . loader -> celery.loaders.app.AppLoader
    . scheduler -> celery.beat.PersistentScheduler
    . db -> celerybeat-schedule
    . logfile -> [stderr]@%WARNING
    . maxinterval -> 5.00 minutes (300s)
[2021-03-27 17:16:58,806: CRITICAL/MainProcess] beat raised exception <class 'EOFError'>: EOFError('Ran out of input')
Traceback (most recent call last):
  File "/home/www/env/lib/python3.9/site-packages/kombu/utils/objects.py", line 41, in __get__
    return obj.__dict__[self.__name__]
KeyError: 'scheduler'

During handling of the above exception, another exception occurred:

Traceback (most recent call last):
  File "/home/www/.python/lib/python3.9/shelve.py", line 111, in __getitem__
    value = self.cache[key]
KeyError: 'entries'

During handling of the above exception, another exception occurred:

Traceback (most recent call last):
  File "/home/www/env/lib/python3.9/site-packages/celery/apps/beat.py", line 105, in start_scheduler
    service.start()
  File "/home/www/env/lib/python3.9/site-packages/celery/beat.py", line 618, in start
    humanize_seconds(self.scheduler.max_interval))
  File "/home/www/env/lib/python3.9/site-packages/kombu/utils/objects.py", line 43, in __get__
    value = obj.__dict__[self.__name__] = self.__get(obj)
  File "/home/www/env/lib/python3.9/site-packages/celery/beat.py", line 662, in scheduler
    return self.get_scheduler()
  File "/home/www/env/lib/python3.9/site-packages/celery/beat.py", line 653, in get_scheduler
    return symbol_by_name(self.scheduler_cls, aliases=aliases)(
  File "/home/www/env/lib/python3.9/site-packages/celery/beat.py", line 497, in __init__
    Scheduler.__init__(self, *args, **kwargs)
  File "/home/www/env/lib/python3.9/site-packages/celery/beat.py", line 253, in __init__
    self.setup_schedule()
  File "/home/www/env/lib/python3.9/site-packages/celery/beat.py", line 525, in setup_schedule
    self._create_schedule()
  File "/home/www/env/lib/python3.9/site-packages/celery/beat.py", line 554, in _create_schedule
    self._store['entries']
  File "/home/www/.python/lib/python3.9/shelve.py", line 114, in __getitem__
    value = Unpickler(f).load()
EOFError: Ran out of input
[2021-03-27 17:16:58,807: WARNING/MainProcess] Aborted!
celery beat v5.0.5 (singularity) is starting.
__    -    ... __   -        _
LocalTime -> 2021-03-27 17:16:58
Configuration ->
    . broker -> redis://localhost:6379/0
    . loader -> celery.loaders.app.AppLoader
    . scheduler -> celery.beat.PersistentScheduler
    . db -> celerybeat-schedule
    . logfile -> [stderr]@%WARNING
    . maxinterval -> 5.00 minutes (300s)
[2021-03-27 17:23:02,718: CRITICAL/MainProcess] beat raised exception <class 'EOFError'>: EOFError('Ran out of input')
Traceback (most recent call last):
  File "/home/www/env/lib/python3.9/site-packages/kombu/utils/objects.py", line 41, in __get__
    return obj.__dict__[self.__name__]
KeyError: 'scheduler'

During handling of the above exception, another exception occurred:

Traceback (most recent call last):
  File "/home/www/.python/lib/python3.9/shelve.py", line 111, in __getitem__
    value = self.cache[key]
KeyError: 'entries'

During handling of the above exception, another exception occurred:

Traceback (most recent call last):
  File "/home/www/env/lib/python3.9/site-packages/celery/apps/beat.py", line 105, in start_scheduler
    service.start()
  File "/home/www/env/lib/python3.9/site-packages/celery/beat.py", line 618, in start
    humanize_seconds(self.scheduler.max_interval))
  File "/home/www/env/lib/python3.9/site-packages/kombu/utils/objects.py", line 43, in __get__
    value = obj.__dict__[self.__name__] = self.__get(obj)
  File "/home/www/env/lib/python3.9/site-packages/celery/beat.py", line 662, in scheduler
    return self.get_scheduler()
  File "/home/www/env/lib/python3.9/site-packages/celery/beat.py", line 653, in get_scheduler
    return symbol_by_name(self.scheduler_cls, aliases=aliases)(
  File "/home/www/env/lib/python3.9/site-packages/celery/beat.py", line 497, in __init__
    Scheduler.__init__(self, *args, **kwargs)
  File "/home/www/env/lib/python3.9/site-packages/celery/beat.py", line 253, in __init__
    self.setup_schedule()
  File "/home/www/env/lib/python3.9/site-packages/celery/beat.py", line 525, in setup_schedule
    self._create_schedule()
  File "/home/www/env/lib/python3.9/site-packages/celery/beat.py", line 554, in _create_schedule
    self._store['entries']
  File "/home/www/.python/lib/python3.9/shelve.py", line 114, in __getitem__
    value = Unpickler(f).load()
EOFError: Ran out of input
[2021-03-27 17:23:02,721: WARNING/MainProcess] Aborted!
celery beat v5.0.5 (singularity) is starting.
__    -    ... __   -        _
LocalTime -> 2021-03-27 17:23:02
Configuration ->
    . broker -> redis://localhost:6379/0
    . loader -> celery.loaders.app.AppLoader
    . scheduler -> celery.beat.PersistentScheduler
    . db -> celerybeat-schedule
    . logfile -> [stderr]@%WARNING
    . maxinterval -> 5.00 minutes (300s)
[2021-03-27 17:23:05,493: CRITICAL/MainProcess] beat raised exception <class 'EOFError'>: EOFError('Ran out of input')
Traceback (most recent call last):
  File "/home/www/env/lib/python3.9/site-packages/kombu/utils/objects.py", line 41, in __get__
    return obj.__dict__[self.__name__]
KeyError: 'scheduler'

During handling of the above exception, another exception occurred:

Traceback (most recent call last):
  File "/home/www/.python/lib/python3.9/shelve.py", line 111, in __getitem__
    value = self.cache[key]
KeyError: 'entries'

During handling of the above exception, another exception occurred:

Traceback (most recent call last):
  File "/home/www/env/lib/python3.9/site-packages/celery/apps/beat.py", line 105, in start_scheduler
    service.start()
  File "/home/www/env/lib/python3.9/site-packages/celery/beat.py", line 618, in start
    humanize_seconds(self.scheduler.max_interval))
  File "/home/www/env/lib/python3.9/site-packages/kombu/utils/objects.py", line 43, in __get__
    value = obj.__dict__[self.__name__] = self.__get(obj)
  File "/home/www/env/lib/python3.9/site-packages/celery/beat.py", line 662, in scheduler
    return self.get_scheduler()
  File "/home/www/env/lib/python3.9/site-packages/celery/beat.py", line 653, in get_scheduler
    return symbol_by_name(self.scheduler_cls, aliases=aliases)(
  File "/home/www/env/lib/python3.9/site-packages/celery/beat.py", line 497, in __init__
    Scheduler.__init__(self, *args, **kwargs)
  File "/home/www/env/lib/python3.9/site-packages/celery/beat.py", line 253, in __init__
    self.setup_schedule()
  File "/home/www/env/lib/python3.9/site-packages/celery/beat.py", line 525, in setup_schedule
    self._create_schedule()
  File "/home/www/env/lib/python3.9/site-packages/celery/beat.py", line 554, in _create_schedule
    self._store['entries']
  File "/home/www/.python/lib/python3.9/shelve.py", line 114, in __getitem__
    value = Unpickler(f).load()
EOFError: Ran out of input
[2021-03-27 17:23:05,579: WARNING/MainProcess] Aborted!
celery beat v5.0.5 (singularity) is starting.
__    -    ... __   -        _
LocalTime -> 2021-03-27 17:23:05
Configuration ->
    . broker -> redis://localhost:6379/0
    . loader -> celery.loaders.app.AppLoader
    . scheduler -> celery.beat.PersistentScheduler
    . db -> celerybeat-schedule
    . logfile -> [stderr]@%WARNING
    . maxinterval -> 5.00 minutes (300s)
[2021-03-27 17:23:08,966: CRITICAL/MainProcess] beat raised exception <class 'EOFError'>: EOFError('Ran out of input')
Traceback (most recent call last):
  File "/home/www/env/lib/python3.9/site-packages/kombu/utils/objects.py", line 41, in __get__
    return obj.__dict__[self.__name__]
KeyError: 'scheduler'

During handling of the above exception, another exception occurred:

Traceback (most recent call last):
  File "/home/www/.python/lib/python3.9/shelve.py", line 111, in __getitem__
    value = self.cache[key]
KeyError: 'entries'

During handling of the above exception, another exception occurred:

Traceback (most recent call last):
  File "/home/www/env/lib/python3.9/site-packages/celery/apps/beat.py", line 105, in start_scheduler
    service.start()
  File "/home/www/env/lib/python3.9/site-packages/celery/beat.py", line 618, in start
    humanize_seconds(self.scheduler.max_interval))
  File "/home/www/env/lib/python3.9/site-packages/kombu/utils/objects.py", line 43, in __get__
    value = obj.__dict__[self.__name__] = self.__get(obj)
  File "/home/www/env/lib/python3.9/site-packages/celery/beat.py", line 662, in scheduler
    return self.get_scheduler()
  File "/home/www/env/lib/python3.9/site-packages/celery/beat.py", line 653, in get_scheduler
    return symbol_by_name(self.scheduler_cls, aliases=aliases)(
  File "/home/www/env/lib/python3.9/site-packages/celery/beat.py", line 497, in __init__
    Scheduler.__init__(self, *args, **kwargs)
  File "/home/www/env/lib/python3.9/site-packages/celery/beat.py", line 253, in __init__
    self.setup_schedule()
  File "/home/www/env/lib/python3.9/site-packages/celery/beat.py", line 525, in setup_schedule
    self._create_schedule()
  File "/home/www/env/lib/python3.9/site-packages/celery/beat.py", line 554, in _create_schedule
    self._store['entries']
  File "/home/www/.python/lib/python3.9/shelve.py", line 114, in __getitem__
    value = Unpickler(f).load()
EOFError: Ran out of input
[2021-03-27 17:23:08,967: WARNING/MainProcess] Aborted!
celery beat v5.0.5 (singularity) is starting.
__    -    ... __   -        _
LocalTime -> 2021-03-27 17:23:08
Configuration ->
    . broker -> redis://localhost:6379/0
    . loader -> celery.loaders.app.AppLoader
    . scheduler -> celery.beat.PersistentScheduler
    . db -> celerybeat-schedule
    . logfile -> [stderr]@%WARNING
    . maxinterval -> 5.00 minutes (300s)
[2021-03-27 17:23:13,320: CRITICAL/MainProcess] beat raised exception <class 'EOFError'>: EOFError('Ran out of input')
Traceback (most recent call last):
  File "/home/www/env/lib/python3.9/site-packages/kombu/utils/objects.py", line 41, in __get__
    return obj.__dict__[self.__name__]
KeyError: 'scheduler'

During handling of the above exception, another exception occurred:

Traceback (most recent call last):
  File "/home/www/.python/lib/python3.9/shelve.py", line 111, in __getitem__
    value = self.cache[key]
KeyError: 'entries'

During handling of the above exception, another exception occurred:

Traceback (most recent call last):
  File "/home/www/env/lib/python3.9/site-packages/celery/apps/beat.py", line 105, in start_scheduler
    service.start()
  File "/home/www/env/lib/python3.9/site-packages/celery/beat.py", line 618, in start
    humanize_seconds(self.scheduler.max_interval))
  File "/home/www/env/lib/python3.9/site-packages/kombu/utils/objects.py", line 43, in __get__
    value = obj.__dict__[self.__name__] = self.__get(obj)
  File "/home/www/env/lib/python3.9/site-packages/celery/beat.py", line 662, in scheduler
    return self.get_scheduler()
  File "/home/www/env/lib/python3.9/site-packages/celery/beat.py", line 653, in get_scheduler
    return symbol_by_name(self.scheduler_cls, aliases=aliases)(
  File "/home/www/env/lib/python3.9/site-packages/celery/beat.py", line 497, in __init__
    Scheduler.__init__(self, *args, **kwargs)
  File "/home/www/env/lib/python3.9/site-packages/celery/beat.py", line 253, in __init__
    self.setup_schedule()
  File "/home/www/env/lib/python3.9/site-packages/celery/beat.py", line 525, in setup_schedule
    self._create_schedule()
  File "/home/www/env/lib/python3.9/site-packages/celery/beat.py", line 554, in _create_schedule
    self._store['entries']
  File "/home/www/.python/lib/python3.9/shelve.py", line 114, in __getitem__
    value = Unpickler(f).load()
EOFError: Ran out of input
[2021-03-27 17:23:13,321: WARNING/MainProcess] Aborted!
celery beat v5.0.5 (singularity) is starting.
__    -    ... __   -        _
LocalTime -> 2021-03-27 17:23:13
Configuration ->
    . broker -> redis://localhost:6379/0
    . loader -> celery.loaders.app.AppLoader
    . scheduler -> celery.beat.PersistentScheduler
    . db -> celerybeat-schedule
    . logfile -> [stderr]@%WARNING
    . maxinterval -> 5.00 minutes (300s)
